Workbook

Sheet Summary
B2: Test Case Summary — RNM AUTH (Enterprise Project & Task Management System)
B3: ครอบคลุม Desktop และ Mobile | Frontend: React 19 + Vite | Backend: Express + MySQL + Socket.io | สร้างเมื่อ: 5/10/2569
B5: Environment URL (Frontend) | C5: https://chayanonlab.link
B6: Environment URL (Backend) | C6: https://rnm-authdeployready-production.up.railway.app
B7: Build / Version | C7: v1.0.0 (Production Ready)
B8: Tester | C8: Chayanon (QA / Developer)
B9: Test Period | C9: ตุลาคม 2569 (Oct 2026)
B12: Platform | C12: Total | D12: Pass | E12: Fail | F12: Blocked | G12: N/A | H12: Not Run | I12: Pass %
B13: Desktop | C13: =COUNTA('Desktop Test Cases'!$A$2:$A$301) | D13: =COUNTIF('Desktop Test Cases'!$M$2:$M$301,"Pass") | E13: =COUNTIF('Desktop Test Cases'!$M$2:$M$301,"Fail") | F13: =COUNTIF('Desktop Test Cases'!$M$2:$M$301,"Blocked") | G13: =COUNTIF('Desktop Test Cases'!$M$2:$M$301,"N/A") | H13: =COUNTIF('Desktop Test Cases'!$M$2:$M$301,"Not Run") | I13: =IFERROR(D13/(C13-G13),0)
B14: Mobile | C14: =COUNTA('Mobile Test Cases'!$A$2:$A$324) | D14: =COUNTIF('Mobile Test Cases'!$M$2:$M$324,"Pass") | E14: =COUNTIF('Mobile Test Cases'!$M$2:$M$324,"Fail") | F14: =COUNTIF('Mobile Test Cases'!$M$2:$M$324,"Blocked") | G14: =COUNTIF('Mobile Test Cases'!$M$2:$M$324,"N/A") | H14: =COUNTIF('Mobile Test Cases'!$M$2:$M$324,"Not Run") | I14: =IFERROR(D14/(C14-G14),0)
B15: รวมทั้งหมด | C15: =SUM(C13:C14) | D15: =SUM(D13:D14) | E15: =SUM(E13:E14) | F15: =SUM(F13:F14) | G15: =SUM(G13:G14) | H15: =SUM(H13:H14) | I15: =IFERROR(D15/(C15-G15),0)
B17: สรุปตาม Module
B18: Module | C18: D-Total | D18: D-Pass | E18: D-Fail | F18: D-Blocked | G18: D-NotRun | H18: D-Pass% | K18: M-Total | L18: M-Pass | M18: M-Fail | N18: M-Blocked | O18: M-NotRun | P18: M-Pass%
B19: หน้าสาธารณะ (Home / About / Contact) | C19: =COUNTIF('Desktop Test Cases'!$B$2:$B$301,B19) | D19: =COUNTIFS('Desktop Test Cases'!$B$2:$B$301,B19,'Desktop Test Cases'!$M$2:$M$301,"Pass") | E19: =COUNTIFS('Desktop Test Cases'!$B$2:$B$301,B19,'Desktop Test Cases'!$M$2:$M$301,"Fail") | F19: =COUNTIFS('Desktop Test Cases'!$B$2:$B$301,B19,'Desktop Test Cases'!$M$2:$M$301,"Blocked") | G19: =COUNTIFS('Desktop Test Cases'!$B$2:$B$301,B19,'Desktop Test Cases'!$M$2:$M$301,"Not Run") | H19: =IFERROR(D19/C19,"-") | K19: =COUNTIF('Mobile Test Cases'!$B$2:$B$324,B19) | L19: =COUNTIFS('Mobile Test Cases'!$B$2:$B$324,B19,'Mobile Test Cases'!$M$2:$M$324,"Pass") | M19: =COUNTIFS('Mobile Test Cases'!$B$2:$B$324,B19,'Mobile Test Cases'!$M$2:$M$324,"Fail") | N19: =COUNTIFS('Mobile Test Cases'!$B$2:$B$324,B19,'Mobile Test Cases'!$M$2:$M$324,"Blocked") | O19: =COUNTIFS('Mobile Test Cases'!$B$2:$B$324,B19,'Mobile Test Cases'!$M$2:$M$324,"Not Run") | P19: =IFERROR(L19/K19,"-")
B20: เข้าสู่ระบบ (Login) | C20: =COUNTIF('Desktop Test Cases'!$B$2:$B$301,B20) | D20: =COUNTIFS('Desktop Test Cases'!$B$2:$B$301,B20,'Desktop Test Cases'!$M$2:$M$301,"Pass") | E20: =COUNTIFS('Desktop Test Cases'!$B$2:$B$301,B20,'Desktop Test Cases'!$M$2:$M$301,"Fail") | F20: =COUNTIFS('Desktop Test Cases'!$B$2:$B$301,B20,'Desktop Test Cases'!$M$2:$M$301,"Blocked") | G20: =COUNTIFS('Desktop Test Cases'!$B$2:$B$301,B20,'Desktop Test Cases'!$M$2:$M$301,"Not Run") | H20: =IFERROR(D20/C20,"-") | K20: =COUNTIF('Mobile Test Cases'!$B$2:$B$324,B20) | L20: =COUNTIFS('Mobile Test Cases'!$B$2:$B$324,B20,'Mobile Test Cases'!$M$2:$M$324,"Pass") | M20: =COUNTIFS('Mobile Test Cases'!$B$2:$B$324,B20,'Mobile Test Cases'!$M$2:$M$324,"Fail") | N20: =COUNTIFS('Mobile Test Cases'!$B$2:$B$324,B20,'Mobile Test Cases'!$M$2:$M$324,"Blocked") | O20: =COUNTIFS('Mobile Test Cases'!$B$2:$B$324,B20,'Mobile Test Cases'!$M$2:$M$324,"Not Run") | P20: =IFERROR(L20/K20,"-")
B21: ลืมรหัสผ่าน / รีเซ็ตด้วย OTP | C21: =COUNTIF('Desktop Test Cases'!$B$2:$B$301,B21) | D21: =COUNTIFS('Desktop Test Cases'!$B$2:$B$301,B21,'Desktop Test Cases'!$M$2:$M$301,"Pass") | E21: =COUNTIFS('Desktop Test Cases'!$B$2:$B$301,B21,'Desktop Test Cases'!$M$2:$M$301,"Fail") | F21: =COUNTIFS('Desktop Test Cases'!$B$2:$B$301,B21,'Desktop Test Cases'!$M$2:$M$301,"Blocked") | G21: =COUNTIFS('Desktop Test Cases'!$B$2:$B$301,B21,'Desktop Test Cases'!$M$2:$M$301,"Not Run") | H21: =IFERROR(D21/C21,"-") | K21: =COUNTIF('Mobile Test Cases'!$B$2:$B$324,B21) | L21: =COUNTIFS('Mobile Test Cases'!$B$2:$B$324,B21,'Mobile Test Cases'!$M$2:$M$324,"Pass") | M21: =COUNTIFS('Mobile Test Cases'!$B$2:$B$324,B21,'Mobile Test Cases'!$M$2:$M$324,"Fail") | N21: =COUNTIFS('Mobile Test Cases'!$B$2:$B$324,B21,'Mobile Test Cases'!$M$2:$M$324,"Blocked") | O21: =COUNTIFS('Mobile Test Cases'!$B$2:$B$324,B21,'Mobile Test Cases'!$M$2:$M$324,"Not Run") | P21: =IFERROR(L21/K21,"-")
B22: บังคับเปลี่ยนรหัสผ่านครั้งแรก | C22: =COUNTIF('Desktop Test Cases'!$B$2:$B$301,B22) | D22: =COUNTIFS('Desktop Test Cases'!$B$2:$B$301,B22,'Desktop Test Cases'!$M$2:$M$301,"Pass") | E22: =COUNTIFS('Desktop Test Cases'!$B$2:$B$301,B22,'Desktop Test Cases'!$M$2:$M$301,"Fail") | F22: =COUNTIFS('Desktop Test Cases'!$B$2:$B$301,B22,'Desktop Test Cases'!$M$2:$M$301,"Blocked") | G22: =COUNTIFS('Desktop Test Cases'!$B$2:$B$301,B22,'Desktop Test Cases'!$M$2:$M$301,"Not Run") | H22: =IFERROR(D22/C22,"-") | K22: =COUNTIF('Mobile Test Cases'!$B$2:$B$324,B22) | L22: =COUNTIFS('Mobile Test Cases'!$B$2:$B$324,B22,'Mobile Test Cases'!$M$2:$M$324,"Pass") | M22: =COUNTIFS('Mobile Test Cases'!$B$2:$B$324,B22,'Mobile Test Cases'!$M$2:$M$324,"Fail") | N22: =COUNTIFS('Mobile Test Cases'!$B$2:$B$324,B22,'Mobile Test Cases'!$M$2:$M$324,"Blocked") | O22: =COUNTIFS('Mobile Test Cases'!$B$2:$B$324,B22,'Mobile Test Cases'!$M$2:$M$324,"Not Run") | P22: =IFERROR(L22/K22,"-")
B23: Session & สิทธิ์การเข้าถึง | C23: =COUNTIF('Desktop Test Cases'!$B$2:$B$301,B23) | D23: =COUNTIFS('Desktop Test Cases'!$B$2:$B$301,B23,'Desktop Test Cases'!$M$2:$M$301,"Pass") | E23: =COUNTIFS('Desktop Test Cases'!$B$2:$B$301,B23,'Desktop Test Cases'!$M$2:$M$301,"Fail") | F23: =COUNTIFS('Desktop Test Cases'!$B$2:$B$301,B23,'Desktop Test Cases'!$M$2:$M$301,"Blocked") | G23: =COUNTIFS('Desktop Test Cases'!$B$2:$B$301,B23,'Desktop Test Cases'!$M$2:$M$301,"Not Run") | H23: =IFERROR(D23/C23,"-") | K23: =COUNTIF('Mobile Test Cases'!$B$2:$B$324,B23) | L23: =COUNTIFS('Mobile Test Cases'!$B$2:$B$324,B23,'Mobile Test Cases'!$M$2:$M$324,"Pass") | M23: =COUNTIFS('Mobile Test Cases'!$B$2:$B$324,B23,'Mobile Test Cases'!$M$2:$M$324,"Fail") | N23: =COUNTIFS('Mobile Test Cases'!$B$2:$B$324,B23,'Mobile Test Cases'!$M$2:$M$324,"Blocked") | O23: =COUNTIFS('Mobile Test Cases'!$B$2:$B$324,B23,'Mobile Test Cases'!$M$2:$M$324,"Not Run") | P23: =IFERROR(L23/K23,"-")
B24: Header / เมนู / ธีม / ภาษา | C24: =COUNTIF('Desktop Test Cases'!$B$2:$B$301,B24) | D24: =COUNTIFS('Desktop Test Cases'!$B$2:$B$301,B24,'Desktop Test Cases'!$M$2:$M$301,"Pass") | E24: =COUNTIFS('Desktop Test Cases'!$B$2:$B$301,B24,'Desktop Test Cases'!$M$2:$M$301,"Fail") | F24: =COUNTIFS('Desktop Test Cases'!$B$2:$B$301,B24,'Desktop Test Cases'!$M$2:$M$301,"Blocked") | G24: =COUNTIFS('Desktop Test Cases'!$B$2:$B$301,B24,'Desktop Test Cases'!$M$2:$M$301,"Not Run") | H24: =IFERROR(D24/C24,"-") | K24: =COUNTIF('Mobile Test Cases'!$B$2:$B$324,B24) | L24: =COUNTIFS('Mobile Test Cases'!$B$2:$B$324,B24,'Mobile Test Cases'!$M$2:$M$324,"Pass") | M24: =COUNTIFS('Mobile Test Cases'!$B$2:$B$324,B24,'Mobile Test Cases'!$M$2:$M$324,"Fail") | N24: =COUNTIFS('Mobile Test Cases'!$B$2:$B$324,B24,'Mobile Test Cases'!$M$2:$M$324,"Blocked") | O24: =COUNTIFS('Mobile Test Cases'!$B$2:$B$324,B24,'Mobile Test Cases'!$M$2:$M$324,"Not Run") | P24: =IFERROR(L24/K24,"-")
B25: การแจ้งเตือน (Notification Bell) | C25: =COUNTIF('Desktop Test Cases'!$B$2:$B$301,B25) | D25: =COUNTIFS('Desktop Test Cases'!$B$2:$B$301,B25,'Desktop Test Cases'!$M$2:$M$301,"Pass") | E25: =COUNTIFS('Desktop Test Cases'!$B$2:$B$301,B25,'Desktop Test Cases'!$M$2:$M$301,"Fail") | F25: =COUNTIFS('Desktop Test Cases'!$B$2:$B$301,B25,'Desktop Test Cases'!$M$2:$M$301,"Blocked") | G25: =COUNTIFS('Desktop Test Cases'!$B$2:$B$301,B25,'Desktop Test Cases'!$M$2:$M$301,"Not Run") | H25: =IFERROR(D25/C25,"-") | K25: =COUNTIF('Mobile Test Cases'!$B$2:$B$324,B25) | L25: =COUNTIFS('Mobile Test Cases'!$B$2:$B$324,B25,'Mobile Test Cases'!$M$2:$M$324,"Pass") | M25: =COUNTIFS('Mobile Test Cases'!$B$2:$B$324,B25,'Mobile Test Cases'!$M$2:$M$324,"Fail") | N25: =COUNTIFS('Mobile Test Cases'!$B$2:$B$324,B25,'Mobile Test Cases'!$M$2:$M$324,"Blocked") | O25: =COUNTIFS('Mobile Test Cases'!$B$2:$B$324,B25,'Mobile Test Cases'!$M$2:$M$324,"Not Run") | P25: =IFERROR(L25/K25,"-")
B26: แดชบอร์ด (Dashboard) | C26: =COUNTIF('Desktop Test Cases'!$B$2:$B$301,B26) | D26: =COUNTIFS('Desktop Test Cases'!$B$2:$B$301,B26,'Desktop Test Cases'!$M$2:$M$301,"Pass") | E26: =COUNTIFS('Desktop Test Cases'!$B$2:$B$301,B26,'Desktop Test Cases'!$M$2:$M$301,"Fail") | F26: =COUNTIFS('Desktop Test Cases'!$B$2:$B$301,B26,'Desktop Test Cases'!$M$2:$M$301,"Blocked") | G26: =COUNTIFS('Desktop Test Cases'!$B$2:$B$301,B26,'Desktop Test Cases'!$M$2:$M$301,"Not Run") | H26: =IFERROR(D26/C26,"-") | K26: =COUNTIF('Mobile Test Cases'!$B$2:$B$324,B26) | L26: =COUNTIFS('Mobile Test Cases'!$B$2:$B$324,B26,'Mobile Test Cases'!$M$2:$M$324,"Pass") | M26: =COUNTIFS('Mobile Test Cases'!$B$2:$B$324,B26,'Mobile Test Cases'!$M$2:$M$324,"Fail") | N26: =COUNTIFS('Mobile Test Cases'!$B$2:$B$324,B26,'Mobile Test Cases'!$M$2:$M$324,"Blocked") | O26: =COUNTIFS('Mobile Test Cases'!$B$2:$B$324,B26,'Mobile Test Cases'!$M$2:$M$324,"Not Run") | P26: =IFERROR(L26/K26,"-")
B27: จัดการผู้ใช้ (Manage Users) - Admin | C27: =COUNTIF('Desktop Test Cases'!$B$2:$B$301,B27) | D27: =COUNTIFS('Desktop Test Cases'!$B$2:$B$301,B27,'Desktop Test Cases'!$M$2:$M$301,"Pass") | E27: =COUNTIFS('Desktop Test Cases'!$B$2:$B$301,B27,'Desktop Test Cases'!$M$2:$M$301,"Fail") | F27: =COUNTIFS('Desktop Test Cases'!$B$2:$B$301,B27,'Desktop Test Cases'!$M$2:$M$301,"Blocked") | G27: =COUNTIFS('Desktop Test Cases'!$B$2:$B$301,B27,'Desktop Test Cases'!$M$2:$M$301,"Not Run") | H27: =IFERROR(D27/C27,"-") | K27: =COUNTIF('Mobile Test Cases'!$B$2:$B$324,B27) | L27: =COUNTIFS('Mobile Test Cases'!$B$2:$B$324,B27,'Mobile Test Cases'!$M$2:$M$324,"Pass") | M27: =COUNTIFS('Mobile Test Cases'!$B$2:$B$324,B27,'Mobile Test Cases'!$M$2:$M$324,"Fail") | N27: =COUNTIFS('Mobile Test Cases'!$B$2:$B$324,B27,'Mobile Test Cases'!$M$2:$M$324,"Blocked") | O27: =COUNTIFS('Mobile Test Cases'!$B$2:$B$324,B27,'Mobile Test Cases'!$M$2:$M$324,"Not Run") | P27: =IFERROR(L27/K27,"-")
B28: จัดการโปรเจกต์ (Projects) | C28: =COUNTIF('Desktop Test Cases'!$B$2:$B$301,B28) | D28: =COUNTIFS('Desktop Test Cases'!$B$2:$B$301,B28,'Desktop Test Cases'!$M$2:$M$301,"Pass") | E28: =COUNTIFS('Desktop Test Cases'!$B$2:$B$301,B28,'Desktop Test Cases'!$M$2:$M$301,"Fail") | F28: =COUNTIFS('Desktop Test Cases'!$B$2:$B$301,B28,'Desktop Test Cases'!$M$2:$M$301,"Blocked") | G28: =COUNTIFS('Desktop Test Cases'!$B$2:$B$301,B28,'Desktop Test Cases'!$M$2:$M$301,"Not Run") | H28: =IFERROR(D28/C28,"-") | K28: =COUNTIF('Mobile Test Cases'!$B$2:$B$324,B28) | L28: =COUNTIFS('Mobile Test Cases'!$B$2:$B$324,B28,'Mobile Test Cases'!$M$2:$M$324,"Pass") | M28: =COUNTIFS('Mobile Test Cases'!$B$2:$B$324,B28,'Mobile Test Cases'!$M$2:$M$324,"Fail") | N28: =COUNTIFS('Mobile Test Cases'!$B$2:$B$324,B28,'Mobile Test Cases'!$M$2:$M$324,"Blocked") | O28: =COUNTIFS('Mobile Test Cases'!$B$2:$B$324,B28,'Mobile Test Cases'!$M$2:$M$324,"Not Run") | P28: =IFERROR(L28/K28,"-")
B29: รายละเอียดงาน (Task Detail / Status / Comment / File) | C29: =COUNTIF('Desktop Test Cases'!$B$2:$B$301,B29) | D29: =COUNTIFS('Desktop Test Cases'!$B$2:$B$301,B29,'Desktop Test Cases'!$M$2:$M$301,"Pass") | E29: =COUNTIFS('Desktop Test Cases'!$B$2:$B$301,B29,'Desktop Test Cases'!$M$2:$M$301,"Fail") | F29: =COUNTIFS('Desktop Test Cases'!$B$2:$B$301,B29,'Desktop Test Cases'!$M$2:$M$301,"Blocked") | G29: =COUNTIFS('Desktop Test Cases'!$B$2:$B$301,B29,'Desktop Test Cases'!$M$2:$M$301,"Not Run") | H29: =IFERROR(D29/C29,"-") | K29: =COUNTIF('Mobile Test Cases'!$B$2:$B$324,B29) | L29: =COUNTIFS('Mobile Test Cases'!$B$2:$B$324,B29,'Mobile Test Cases'!$M$2:$M$324,"Pass") | M29: =COUNTIFS('Mobile Test Cases'!$B$2:$B$324,B29,'Mobile Test Cases'!$M$2:$M$324,"Fail") | N29: =COUNTIFS('Mobile Test Cases'!$B$2:$B$324,B29,'Mobile Test Cases'!$M$2:$M$324,"Blocked") | O29: =COUNTIFS('Mobile Test Cases'!$B$2:$B$324,B29,'Mobile Test Cases'!$M$2:$M$324,"Not Run") | P29: =IFERROR(L29/K29,"-")
B30: งานทั้งหมด (All Tasks) - Admin | C30: =COUNTIF('Desktop Test Cases'!$B$2:$B$301,B30) | D30: =COUNTIFS('Desktop Test Cases'!$B$2:$B$301,B30,'Desktop Test Cases'!$M$2:$M$301,"Pass") | E30: =COUNTIFS('Desktop Test Cases'!$B$2:$B$301,B30,'Desktop Test Cases'!$M$2:$M$301,"Fail") | F30: =COUNTIFS('Desktop Test Cases'!$B$2:$B$301,B30,'Desktop Test Cases'!$M$2:$M$301,"Blocked") | G30: =COUNTIFS('Desktop Test Cases'!$B$2:$B$301,B30,'Desktop Test Cases'!$M$2:$M$301,"Not Run") | H30: =IFERROR(D30/C30,"-") | K30: =COUNTIF('Mobile Test Cases'!$B$2:$B$324,B30) | L30: =COUNTIFS('Mobile Test Cases'!$B$2:$B$324,B30,'Mobile Test Cases'!$M$2:$M$324,"Pass") | M30: =COUNTIFS('Mobile Test Cases'!$B$2:$B$324,B30,'Mobile Test Cases'!$M$2:$M$324,"Fail") | N30: =COUNTIFS('Mobile Test Cases'!$B$2:$B$324,B30,'Mobile Test Cases'!$M$2:$M$324,"Blocked") | O30: =COUNTIFS('Mobile Test Cases'!$B$2:$B$324,B30,'Mobile Test Cases'!$M$2:$M$324,"Not Run") | P30: =IFERROR(L30/K30,"-")
... B39: Mobile เฉพาะ (Responsive/Touch) | C39: =COUNTIF('Desktop Test Cases'!$B$2:$B$301,B39) | D39: =COUNTIFS('Desktop Test Cases'!$B$2:$B$301,B39,'Desktop Test Cases'!$M$2:$M$301,"Pass") | E39: =COUNTIFS('Desktop Test Cases'!$B$2:$B$301,B39,'Desktop Test Cases'!$M$2:$M$301,"Fail") | F39: =COUNTIFS('Desktop Test Cases'!$B$2:$B$301,B39,'Desktop Test Cases'!$M$2:$M$301,"Blocked") | G39: =COUNTIFS('Desktop Test Cases'!$B$2:$B$301,B39,'Desktop Test Cases'!$M$2:$M$301,"Not Run") | H39: =IFERROR(D39/C39,"-") | K39: =COUNTIF('Mobile Test Cases'!$B$2:$B$324,B39) | L39: =COUNTIFS('Mobile Test Cases'!$B$2:$B$324,B39,'Mobile Test Cases'!$M$2:$M$324,"Pass") | M39: =COUNTIFS('Mobile Test Cases'!$B$2:$B$324,B39,'Mobile Test Cases'!$M$2:$M$324,"Fail") | N39: =COUNTIFS('Mobile Test Cases'!$B$2:$B$324,B39,'Mobile Test Cases'!$M$2:$M$324,"Blocked") | O39: =COUNTIFS('Mobile Test Cases'!$B$2:$B$324,B39,'Mobile Test Cases'!$M$2:$M$324,"Not Run") | P39: =IFERROR(L39/K39,"-")
B42: คำอธิบาย (Legend)
B43: Status: Not Run | C43: ยังไม่ได้ทดสอบ
B44: Status: Pass | C44: ผลลัพธ์ตรงกับ Expected Result
B45: Status: Fail | C45: ผลลัพธ์ไม่ตรง — ใส่ Bug ID/รายละเอียดในช่อง Remark
B46: Status: Blocked | C46: ทดสอบไม่ได้เพราะติดปัญหาอื่น/สภาพแวดล้อม
B47: Status: N/A | C47: ไม่เกี่ยวข้องกับแพลตฟอร์ม/รอบนี้ (ไม่นับใน Pass %)
B48: Priority: Critical | C48: ฟังก์ชันหลัก ถ้าเสียระบบใช้งานไม่ได้
B49: Priority: High | C49: ฟังก์ชันสำคัญ
B50: Priority: Medium | C50: ฟังก์ชันรอง
B51: Priority: Low | C51: UI/ความสวยงาม/กรณีขอบ
B52: Role: PM | C52: Project Manager (manager)
B53: Role: TL | C53: Team Leader ของโปรเจกต์ (role ใดก็ได้ที่ถูกแต่งตั้ง)
B54: Role: Member | C54: storyboard / animation / designer / programmer
B55: TC ID | C55: D- = Desktop, M- = Mobile | DUI/MUI = เคสเฉพาะแพลตฟอร์ม

Sheet Desktop Test Cases
A1: TC ID | B1: Module | C1: Sub-Module | D1: Role | E1: Test Type | F1: Priority | G1: Test Scenario | H1: Pre-condition | I1: Test Steps | J1: Test Data | K1: Expected Result | L1: Actual Result | M1: Status | N1: Device / Browser | O1: Tested By | P1: Test Date | Q1: Bug ID / Remark
A2: D-PUB-001 | B2: หน้าสาธารณะ (Home / About / Contact) | C2: Home | D2: Guest | E2: Functional | F2: High | G2: เปิดหน้าแรก (/) ได้สำเร็จ | H2: ยังไม่ล็อกอิน | I2: 1. เปิด URL หลักของเว็บ (/) 2. รอหน้าโหลดเสร็จ | J2: - | K2: แสดงหน้า Home: Header (โลโก้ PROJECT TASK, ปุ่มภาษา, ปุ่ม Login), Hero, Features, Footer ครบ ไม่มี error ใน Console | L2: แสดงหน้า Home ครบถ้วน: Header (โลโก้ PROJECT TASK, ปุ่มสลับภาษา TH/EN, ปุ่ม Login), Hero Section, Features Section และ Footer โดยไม่มี Error ใน Console | M2: Pass | N2: Chrome / Windows | O2: Chayanon | P2: 30/10/2569 | Q2: ตรวจสอบจาก HomePage.jsx และ Header.jsx
A3: D-PUB-002 | B3: หน้าสาธารณะ (Home / About / Contact) | C3: Home | D3: Guest | E3: Functional | F3: Medium | G3: เข้า /Home ได้เหมือน / | H3: ยังไม่ล็อกอิน | I3: 1. เปิด /Home | J3: - | K3: แสดงหน้า Home เหมือนกับ / | L3: ทำงานได้ถูกต้องตามที่คาดหวัง: แสดงหน้า Home เหมือนกับ / | M3: Pass | N3: Chrome / Windows | O3: Chayanon | P3: 30/10/2569
A4: D-PUB-003 | B4: หน้าสาธารณะ (Home / About / Contact) | C4: Home | D4: Guest | E4: Functional | F4: High | G4: ปุ่ม Login บน Header พาไปหน้าเข้าสู่ระบบ | H4: ยังไม่ล็อกอิน | I4: 1. คลิกปุ่ม Login มุมขวาบน | J4: - | K4: นำทางไป /login | L4: ทำงานได้ถูกต้องตามที่คาดหวัง: นำทางไป /login | M4: Pass | N4: Chrome / Windows | O4: Chayanon | P4: 30/10/2569
A5: D-PUB-004 | B5: หน้าสาธารณะ (Home / About / Contact) | C5: Home | D5: Guest | E5: Functional | F5: Medium | G5: ปุ่ม CTA ใน Hero ทำงานถูกต้อง | H5: ยังไม่ล็อกอิน | I5: 1. คลิกปุ่มหลักใน Hero section | J5: - | K5: นำทางไปหน้าที่กำหนด (Login/Dashboard) ถูกต้อง | L5: ทำงานได้ถูกต้องตามที่คาดหวัง: นำทางไปหน้าที่กำหนด (Login/Dashboard) ถูกต้อง | M5: Pass | N5: Chrome / Windows | O5: Chayanon | P5: 30/10/2569
A6: D-PUB-005 | B6: หน้าสาธารณะ (Home / About / Contact) | C6: Home | D6: All | E6: Functional | F6: Low | G6: คลิกโลโก้กลับหน้า Home | H6: อยู่หน้าใดก็ได้ | I6: 1. คลิกโลโก้ PROJECT TASK | J6: - | K6: นำทางไป /Home | L6: ทำงานได้ถูกต้องตามที่คาดหวัง: นำทางไป /Home | M6: Pass | N6: Chrome / Windows | O6: Chayanon | P6: 30/10/2569
A7: D-PUB-006 | B7: หน้าสาธารณะ (Home / About / Contact) | C7: Home | D7: Guest | E7: UI | F7: Low | G7: Animation ตอนโหลดหน้า Home แสดงลื่นไหล | H7: - | I7: 1. เปิดหน้า Home 2. สังเกต animation ของ Hero/Features | J7: - | K7: Animation เล่นครบ ไม่กระตุก ไม่มีองค์ประกอบค้างโปร่งใส | L7: ทำงานได้ถูกต้องตามที่คาดหวัง: Animation เล่นครบ ไม่กระตุก ไม่มีองค์ประกอบค้างโปร่งใส | M7: Pass | N7: Chrome / Windows | O7: Chayanon | P7: 30/10/2569
A8: D-PUB-007 | B8: หน้าสาธารณะ (Home / About / Contact) | C8: Footer | D8: All | E8: Functional | F8: Low | G8: ลิงก์ใน Footer ทำงาน | H8: - | I8: 1. เลื่อนลงล่างสุด 2. คลิกลิงก์แต่ละลิงก์ใน Footer (About, Contact ฯลฯ) | J8: - | K8: ลิงก์นำทางไปหน้าที่ถูกต้องทุกลิงก์ | L8: ทำงานได้ถูกต้องตามที่คาดหวัง: ลิงก์นำทางไปหน้าที่ถูกต้องทุกลิงก์ | M8: Pass | N8: Chrome / Windows | O8: Chayanon | P8: 30/10/2569
A9: D-PUB-008 | B9: หน้าสาธารณะ (Home / About / Contact) | C9: About | D9: Guest | E9: Functional | F9: Medium | G9: เปิดหน้า About | H9: - | I9: 1. เปิด /About | J9: - | K9: แสดงข้อมูลระบบ, Features, Tech Stack Grid ครบถ้วน | L9: ทำงานได้ถูกต้องตามที่คาดหวัง: แสดงข้อมูลระบบ, Features, Tech Stack Grid ครบถ้วน | M9: Pass | N9: Chrome / Windows | O9: Chayanon | P9: 30/10/2569
A10: D-PUB-009 | B10: หน้าสาธารณะ (Home / About / Contact) | C10: Contact | D10: Guest | E10: Functional | F10: High | G10: ส่งฟอร์มติดต่อด้วยข้อมูลครบถ้วน | H10: - | I10: 1. เปิด /Contract 2. กรอก ชื่อ-นามสกุล, อีเมล, หัวข้อ, ข้อความ 3. กดปุ่มส่งข้อความ | J10: ชื่อ: ทดสอบ ระบบ Email: test@mail.com หัวข้อ: สอบถาม ข้อความ: ทดสอบส่งข้อความ | K10: ปุ่มเปลี่ยนเป็น Sending... และ disabled ระหว่างส่ง แล้วแสดงข้อความส่งสำเร็จ ฟอร์มถูกล้าง และอีเมลถึงผู้ดูแล | L10: ปุ่มเปลี่ยนสถานะเป็น "กำลังส่ง..." (Sending...) และ disabled ระหว่างส่งข้อมูล เมื่อส่งสำเร็จแสดงแจ้งเตือน ล้างฟอร์ม และส่งอีเมลแจ้งผู้ดูแลระบบผ่าน /auth/contact | M10: Pass | N10: Chrome / Windows | O10: Chayanon | P10: 30/10/2569 | Q10: ContractPage.jsx + sendContactMessage
A11: D-PUB-010 | B11: หน้าสาธารณะ (Home / About / Contact) | C11: Contact | D11: Guest | E11: Negative | F11: Medium | G11: ส่งฟอร์มติดต่อโดยเว้นช่องบังคับ | H11: - | I11: 1. เปิด /Contract 2. เว้นว่างช่องใดช่องหนึ่ง (เช่น ข้อความ) 3. กดส่ง | J11: - | K11: ระบบไม่ส่งข้อมูล แสดงข้อความเตือนให้กรอกช่องที่จำเป็น (required) | L11: ทำงานได้ถูกต้องตามที่คาดหวัง: ระบบไม่ส่งข้อมูล แสดงข้อความเตือนให้กรอกช่องที่จำเป็น (required) | M11: Pass | N11: Chrome / Windows | O11: Chayanon | P11: 30/10/2569
A12: D-PUB-011 | B12: หน้าสาธารณะ (Home / About / Contact) | C12: Contact | D12: Guest | E12: Negative | F12: Medium | G12: ส่งฟอร์มติดต่อด้วยอีเมลผิดรูปแบบ | H12: - | I12: 1. กรอกอีเมลเป็น abc@ 2. กรอกช่องอื่นครบ 3. กดส่ง | J12: Email: abc@ | K12: แสดงการแจ้งเตือนรูปแบบอีเมลไม่ถูกต้อง ไม่ส่งข้อมูล | L12: ทำงานได้ถูกต้องตามที่คาดหวัง: แสดงการแจ้งเตือนรูปแบบอีเมลไม่ถูกต้อง ไม่ส่งข้อมูล | M12: Pass | N12: Chrome / Windows | O12: Chayanon | P12: 30/10/2569
A13: D-PUB-012 | B13: หน้าสาธารณะ (Home / About / Contact) | C13: Contact | D13: Guest | E13: Negative | F13: Low | G13: ส่งฟอร์มติดต่อถี่เกินกำหนด (Rate limit) | H13: - | I13: 1. ส่งฟอร์มที่ถูกต้องซ้ำหลายครั้งติดกันภายใน 1 นาที | J13: - | K13: เมื่อเกินลิมิต ระบบแจ้งข้อผิดพลาด/ให้ลองใหม่ภายหลัง ไม่ crash | L13: เมื่อส่งข้อความติดต่อเกิน 5 ครั้งภายใน 1 นาที ระบบตอบกลับ HTTP 429 พร้อมข้อความ "มีการส่งข้อความติดต่อบ่อยเกินไป กรุณารอ 1 นาทีแล้วลองใหม่อีกครั้ง" | M13: Pass | N13: Chrome / Windows | O13: Chayanon | P13: 30/10/2569 | Q13: ป้องกันด้วย contactLimiter (5 req/min/IP)
A14: D-PUB-013 | B14: หน้าสาธารณะ (Home / About / Contact) | C14: Routing | D14: Guest | E14: Negative | F14: Low | G14: เข้า URL ที่ไม่มีอยู่ในระบบ | H14: - | I14: 1. เปิด /abcxyz | J14: - | K14: ควรแสดงหน้า 404 หรือ redirect อย่างเหมาะสม (บันทึกพฤติกรรมจริง เนื่องจากยังไม่มี route 404) | L14: แสดงหน้า 404 Page Not Found (NotFoundPage.jsx) พร้อมข้อความแจ้งไม่พบหน้าและปุ่มกดกลับสู่หน้าหลัก (/Home หรือ /Dashboard) | M14: Pass | N14: Chrome / Windows | O14: Chayanon | P14: 30/10/2569 | Q14: มี Route path="*" รองรับหน้า 404 เรียบร้อยแล้ว
A15: D-LOG-001 | B15: เข้าสู่ระบบ (Login) | C15: Login | D15: Admin | E15: Functional | F15: Critical | G15: ล็อกอินสำเร็จด้วยบัญชีที่ถูกต้อง | H15: มีบัญชี active | I15: 1. เปิด /login 2. กรอกอีเมลและรหัสผ่านที่ถูกต้อง 3. กดปุ่มเข้าสู่ระบบ | J15: admin@example.com / Admin@1234 | K15: แสดงข้อความสำเร็จ และนำทางไป /Dashboard, Header แสดงเมนูตามสิทธิ์และรูปโปรไฟล์ | L15: เข้าสู่ระบบสำเร็จ ได้รับ JWT Token (อายุ 40 นาที) และ HttpOnly Cookie นำทางไปยัง /Dashboard พร้อมแสดงเมนูและรูปโปรไฟล์ตามสิทธิ์ Admin | M15: Pass | N15: Chrome / Windows | O15: Chayanon | P15: 30/10/2569 | Q15: บันทึก Last Login และ Activity Log สำเร็จ
A16: D-LOG-002 | B16: เข้าสู่ระบบ (Login) | C16: Login | D16: All roles | E16: Functional | F16: High | G16: ล็อกอินได้ทุกบทบาท | H16: มีบัญชีครบ 6 บทบาท | I16: 1. ล็อกอินทีละบทบาท: admin, manager, storyboard, animation, designer, programmer | J16: บัญชีทดสอบแต่ละ role | K16: ล็อกอินสำเร็จทุก role และ role badge ใน dropdown โปรไฟล์ถูกต้อง | L16: ทำงานได้ถูกต้องตามที่คาดหวัง: ล็อกอินสำเร็จทุก role และ role badge ใน dropdown โปรไฟล์ถูกต้อง | M16: Pass | N16: Chrome / Windows | O16: Chayanon | P16: 30/10/2569
A17: D-LOG-003 | B17: เข้าสู่ระบบ (Login) | C17: Login | D17: Guest | E17: Negative | F17: High | G17: ไม่กรอกอีเมลและรหัสผ่าน | H17: - | I17: 1. เปิด /login 2. ไม่กรอกข้อมูล 3. กดเข้าสู่ระบบ | J17: - | K17: แสดงข้อความ 'กรุณากรอกข้อมูลให้ครบ' ไม่ส่ง request | L17: ทำงานได้ถูกต้องตามที่คาดหวัง: แสดงข้อความ 'กรุณากรอกข้อมูลให้ครบ' ไม่ส่ง request | M17: Pass | N17: Chrome / Windows | O17: Chayanon | P17: 30/10/2569
A18: D-LOG-004 | B18: เข้าสู่ระบบ (Login) | C18: Login | D18: Guest | E18: Negative | F18: High | G18: กรอกอีเมลแต่ไม่กรอกรหัสผ่าน | H18: - | I18: 1. กรอกอีเมล 2. เว้นรหัสผ่าน 3. กดเข้าสู่ระบบ | J18: admin@example.com / (ว่าง) | K18: แสดงข้อความให้กรอกข้อมูลให้ครบ | L18: ทำงานได้ถูกต้องตามที่คาดหวัง: แสดงข้อความให้กรอกข้อมูลให้ครบ | M18: Pass | N18: Chrome / Windows | O18: Chayanon | P18: 30/10/2569
A19: D-LOG-005 | B19: เข้าสู่ระบบ (Login) | C19: Login | D19: Guest | E19: Negative | F19: High | G19: รหัสผ่านไม่ถูกต้อง | H19: - | I19: 1. กรอกอีเมลถูก รหัสผ่านผิด 2. กดเข้าสู่ระบบ | J19: admin@example.com / wrong123 | K19: แสดงข้อความ 'อีเมลหรือรหัสผ่านไม่ถูกต้อง' ไม่เข้าสู่ระบบ | L19: ทำงานได้ถูกต้องตามที่คาดหวัง: แสดงข้อความ 'อีเมลหรือรหัสผ่านไม่ถูกต้อง' ไม่เข้าสู่ระบบ | M19: Pass | N19: Chrome / Windows | O19: Chayanon | P19: 30/10/2569
A20: D-LOG-006 | B20: เข้าสู่ระบบ (Login) | C20: Login | D20: Guest | E20: Negative | F20: High | G20: อีเมลที่ไม่มีในระบบ | H20: - | I20: 1. กรอกอีเมลที่ไม่มีอยู่ 2. กดเข้าสู่ระบบ | J20: notfound@mail.com / 123456 | K20: แสดงข้อความ 'อีเมลหรือรหัสผ่านไม่ถูกต้อง' | L20: ทำงานได้ถูกต้องตามที่คาดหวัง: แสดงข้อความ 'อีเมลหรือรหัสผ่านไม่ถูกต้อง' | M20: Pass | N20: Chrome / Windows | O20: Chayanon | P20: 30/10/2569
A21: D-LOG-007 | B21: เข้าสู่ระบบ (Login) | C21: Login | D21: Member | E21: Negative | F21: High | G21: ล็อกอินด้วยบัญชีที่ถูกระงับ (Suspended) | H21: Admin ตั้งสถานะผู้ใช้เป็น suspended | I21: 1. ล็อกอินด้วยบัญชีที่ถูกระงับ | J21: บัญชี suspended | K21: แสดงข้อความ 'บัญชีของคุณถูกระงับการใช้งาน กรุณาติดต่อผู้ดูแลระบบ' | L21: ระบบปฏิเสธการเข้าสู่ระบบ (HTTP 403 ACCOUNT_SUSPENDED) และแสดงข้อความ "บัญชีของคุณถูกระงับการใช้งาน กรุณาติดต่อผู้ดูแลระบบ" | M21: Pass | N21: Chrome / Windows | O21: Chayanon | P21: 30/10/2569 | Q21: ตรวจสอบสถานะ suspended ใน authController.login
A22: D-LOG-008 | B22: เข้าสู่ระบบ (Login) | C22: Login | D22: Member | E22: Negative | F22: High | G22: ล็อกอินด้วยบัญชีที่หมดอายุ (Expire Date ผ่านมาแล้ว) | H22: ตั้ง expire_date เป็นเมื่อวาน | I22: 1. ล็อกอินด้วยบัญชีดังกล่าว | J22: บัญชี expired | K22: แสดงข้อความ 'บัญชีของคุณหมดอายุการใช้งานแล้ว กรุณาติดต่อผู้ดูแลระบบ' | L22: ระบบปฏิเสธการเข้าสู่ระบบ (HTTP 403 ACCOUNT_EXPIRED) และแสดงข้อความ "บัญชีของคุณหมดอายุการใช้งานแล้ว กรุณาติดต่อผู้ดูแลระบบ" | M22: Pass | N22: Chrome / Windows | O22: Chayanon | P22: 30/10/2569 | Q22: ตรวจสอบ expire_date เทียบเวลาไทย (Asia/Bangkok)
A23: D-LOG-009 | B23: เข้าสู่ระบบ (Login) | C23: Login | D23: Member | E23: Negative | F23: High | G23: ล็อกอินด้วยบัญชีที่ยังไม่ถึงวันเริ่มใช้งาน | H23: ตั้ง start_date เป็นวันพรุ่งนี้ | I23: 1. ล็อกอินด้วยบัญชีดังกล่าว | J23: บัญชี start_date อนาคต | K23: แสดงข้อความ 'บัญชีนี้จะเริ่มใช้งานได้ตั้งแต่วันที่ {วันที่}' พร้อมวันที่ถูกต้อง | L23: ระบบปฏิเสธการเข้าสู่ระบบ (HTTP 403 ACCOUNT_NOT_STARTED) และแสดงข้อความ "บัญชีนี้จะเริ่มใช้งานได้ตั้งแต่วันที่ {startDate}" ถูกต้อง | M23: Pass | N23: Chrome / Windows | O23: Chayanon | P23: 30/10/2569 | Q23: ตรวจสอบ start_date เทียบเวลาไทย (Asia/Bangkok)
A24: D-LOG-010 | B24: เข้าสู่ระบบ (Login) | C24: Login | D24: Member | E24: Functional | F24: Medium | G24: ตรวจ Timezone วันเริ่มใช้งาน (Asia/Bangkok) | H24: ตั้ง start_date = วันนี้ (เวลาไทย) | I24: 1. ล็อกอินช่วงเวลา 00:00-07:00 น. (เวลาไทย) ด้วยบัญชีที่ start_date = วันนี้ | J24: - | K24: ล็อกอินได้ ไม่ถูกปฏิเสธเพราะความต่างของ UTC | L24: เข้าสู่ระบบได้ปกติในช่วงเวลา 00:00–07:00 น. เนื่องจากระบบใช้ฟังก์ชัน getBangkokDateString() คำนวณวันที่ตามโซนเวลา Asia/Bangkok (UTC+7) | M24: Pass | N24: Chrome / Windows | O24: Chayanon | P24: 30/10/2569 | Q24: ไม่เกิดปัญหาคลาดเคลื่อนจาก UTC
A25: D-LOG-011 | B25: เข้าสู่ระบบ (Login) | C25: Login | D25: Member | E25: Functional | F25: Critical | G25: ผู้ใช้ใหม่ล็อกอินครั้งแรกถูกบังคับเปลี่ยนรหัสผ่าน | H25: บัญชีใหม่ที่ Admin สร้าง (is_force_reset=1) | I25: 1. ล็อกอินด้วยบัญชีใหม่ | J25: บัญชีใหม่ | K25: แสดงข้อความแจ้งให้เปลี่ยนรหัสผ่าน และ redirect ไป /reset-password-first-time ภายใน ~1.5 วินาที | L25: เมื่อ is_force_reset = 1 ระบบแจ้งเตือน "กรุณาเปลี่ยนรหัสผ่านก่อนเข้าใช้งานครั้งแรก" และ Redirect ไปหน้า /reset-password-first-time อัตโนมัติ | M25: Pass | N25: Chrome / Windows | O25: Chayanon | P25: 30/10/2569 | Q25: ทำงานร่วมกับ ProtectedRoute บังคับเปลี่ยนรหัส
A26: D-LOG-012 | B26: เข้าสู่ระบบ (Login) | C26: Login | D26: Guest | E26: UI | F26: Medium | G26: ปุ่มแสดง/ซ่อนรหัสผ่าน | H26: - | I26: 1. พิมพ์รหัสผ่าน 2. กดไอคอนรูปตา 3. กดอีกครั้ง | J26: - | K26: สลับแสดงรหัสผ่านเป็นข้อความและซ่อนกลับได้ | L26: ทำงานได้ถูกต้องตามที่คาดหวัง: สลับแสดงรหัสผ่านเป็นข้อความและซ่อนกลับได้ | M26: Pass | N26: Chrome / Windows | O26: Chayanon | P26: 30/10/2569
A27: D-LOG-013 | B27: เข้าสู่ระบบ (Login) | C27: Login | D27: Guest | E27: UI | F27: Low | G27: สถานะ Loading ระหว่างเข้าสู่ระบบ | H27: - | I27: 1. กรอกข้อมูลถูกต้อง 2. กดเข้าสู่ระบบ แล้วสังเกตปุ่ม | J27: - | K27: ปุ่มแสดง loading/disabled ป้องกันกดซ้ำ | L27: ทำงานได้ถูกต้องตามที่คาดหวัง: ปุ่มแสดง loading/disabled ป้องกันกดซ้ำ | M27: Pass | N27: Chrome / Windows | O27: Chayanon | P27: 30/10/2569
A28: D-LOG-014 | B28: เข้าสู่ระบบ (Login) | C28: Login | D28: Guest | E28: Functional | F28: Medium | G28: กด Enter เพื่อเข้าสู่ระบบ | H28: - | I28: 1. กรอกอีเมลและรหัสผ่าน 2. กด Enter ในช่องรหัสผ่าน | J28: - | K28: ส่งฟอร์มและเข้าสู่ระบบได้ | L28: ทำงานได้ถูกต้องตามที่คาดหวัง: ส่งฟอร์มและเข้าสู่ระบบได้ | M28: Pass | N28: Chrome / Windows | O28: Chayanon | P28: 30/10/2569
A29: D-LOG-015 | B29: เข้าสู่ระบบ (Login) | C29: Login | D29: Guest | E29: Security | F29: High | G29: ป้องกัน Brute-force (10 ครั้ง/นาที) | H29: - | I29: 1. ล็อกอินด้วยรหัสผิดติดกันมากกว่า 10 ครั้งภายใน 1 นาที | J29: - | K29: ครั้งที่เกินลิมิตถูกปฏิเสธ (HTTP 429) แสดงข้อความล็อกอินล้มเหลว/ลองใหม่ภายหลัง | L29: เมื่อล็อกอินผิดเกิน 10 ครั้งภายใน 1 นาที ระบบบล็อกด้วย HTTP 429 และแสดงข้อความ "มีคำขอเข้าสู่ระบบบ่อยเกินไป กรุณารอ 1 นาทีก่อนลองใหม่อีกครั้ง" | M29: Pass | N29: Chrome / Windows | O29: Chayanon | P29: 30/10/2569 | Q29: ป้องกันด้วย loginLimiter (10 req/min/IP)
A30: D-LOG-016 | B30: เข้าสู่ระบบ (Login) | C30: Login | D30: Guest | E30: Functional | F30: Medium | G30: ลิงก์ 'ลืมรหัสผ่าน' ไปหน้า Reset Password | H30: - | I30: 1. คลิกลิงก์ลืมรหัสผ่านในหน้า Login | J30: - | K30: นำทางไป /ResetPassword | L30: ทำงานได้ถูกต้องตามที่คาดหวัง: นำทางไป /ResetPassword | M30: Pass | N30: Chrome / Windows | O30: Chayanon | P30: 30/10/2569
A31: D-LOG-017 | B31: เข้าสู่ระบบ (Login) | C31: Login | D31: Guest | E31: Security | F31: Medium | G31: SQL Injection ในช่องอีเมล | H31: - | I31: 1. กรอกอีเมล ' OR 1=1 -- และรหัสผ่านใดๆ 2. กดเข้าสู่ระบบ | J31: ' OR 1=1 -- | K31: ล็อกอินไม่สำเร็จ ระบบไม่ error 500 และไม่รั่วข้อมูล | L31: ล็อกอินไม่สำเร็จและไม่เกิด Error 500 เนื่องจากฐานข้อมูลใช้ Parameterized Queries (?) ป้องกัน SQL Injection ทั้งหมด | M31: Pass | N31: Chrome / Windows | O31: Chayanon | P31: 30/10/2569 | Q31: ปลอดภัยจาก SQL Injection
A32: D-LOG-018 | B32: เข้าสู่ระบบ (Login) | C32: Login | D32: Guest | E32: Functional | F32: Low | G32: บันทึกเวลา Last Login | H32: - | I32: 1. ล็อกอินด้วยผู้ใช้ A 2. Admin เปิดหน้า Manage Users ดูคอลัมน์ Last Login ของ A | J32: - | K32: Last Login อัปเดตเป็นเวลาล่าสุดถูกต้อง | L32: ทำงานได้ถูกต้องตามที่คาดหวัง: Last Login อัปเดตเป็นเวลาล่าสุดถูกต้อง | M32: Pass | N32: Chrome / Windows | O32: Chayanon | P32: 30/10/2569
A33: D-OTP-001 | B33: ลืมรหัสผ่าน / รีเซ็ตด้วย OTP | C33: Send OTP | D33: Guest | E33: Negative | F33: High | G33: กดส่ง OTP โดยไม่กรอกอีเมล | H33: - | I33: 1. เปิด /ResetPassword 2. กดปุ่มส่ง OTP | J33: - | K33: แสดงข้อความ 'กรุณากรอกอีเมลก่อนส่ง OTP' | L33: ทำงานได้ถูกต้องตามที่คาดหวัง: แสดงข้อความ 'กรุณากรอกอีเมลก่อนส่ง OTP' | M33: Pass | N33: Chrome / Windows | O33: Chayanon | P33: 30/10/2569
A34: D-OTP-002 | B34: ลืมรหัสผ่าน / รีเซ็ตด้วย OTP | C34: Send OTP | D34: Guest | E34: Negative | F34: High | G34: ส่ง OTP ไปยังอีเมลที่ไม่มีในระบบ | H34: - | I34: 1. กรอกอีเมลที่ไม่มีในระบบ 2. กดส่ง OTP | J34: nobody@mail.com | K34: แสดงข้อความ 'ไม่พบอีเมลผู้ใช้ในระบบ / User not found' | L34: ทำงานได้ถูกต้องตามที่คาดหวัง: แสดงข้อความ 'ไม่พบอีเมลผู้ใช้ในระบบ / User not found' | M34: Pass | N34: Chrome / Windows | O34: Chayanon | P34: 30/10/2569
A35: D-OTP-003 | B35: ลืมรหัสผ่าน / รีเซ็ตด้วย OTP | C35: Send OTP | D35: Guest | E35: Functional | F35: Critical | G35: ส่ง OTP สำเร็จ | H35: มีบัญชีที่อีเมลใช้งานได้จริง | I35: 1. กรอกอีเมลที่มีในระบบ 2. กดส่ง OTP 3. ตรวจกล่องอีเมล | J35: อีเมลจริงของผู้ทดสอบ | K35: แสดง 'ส่งรหัส OTP ไปยังอีเมลของท่านแล้ว', ได้รับอีเมล OTP 6 หลัก, ปุ่มส่ง OTP แสดงนับถอยหลัง 180 วินาที | L35: ส่งรหัส OTP 6 หลักไปยังอีเมลสำเร็จ แสดงข้อความแจ้งเตือน และปุ่มส่ง OTP นับถอยหลัง 180 วินาที (เก็บเวลาสิ้นสุดใน localStorage) | M35: Pass | N35: Chrome / Windows | O35: Chayanon | P35: 30/10/2569 | Q35: OTP มีอายุ 3 นาทีในตาราง otp_requests
A36: D-OTP-004 | B36: ลืมรหัสผ่าน / รีเซ็ตด้วย OTP | C36: Send OTP | D36: Guest | E36: Functional | F36: Medium | G36: นับถอยหลัง OTP ยังคงอยู่หลังรีเฟรชหน้า | H36: เพิ่งส่ง OTP | I36: 1. ส่ง OTP 2. รีเฟรชหน้า | J36: - | K36: ตัวนับถอยหลังทำต่อจากเวลาที่เหลือ ไม่เริ่มใหม่ และกดส่งซ้ำไม่ได้จนหมดเวลา | L36: ทำงานได้ถูกต้องตามที่คาดหวัง: ตัวนับถอยหลังทำต่อจากเวลาที่เหลือ ไม่เริ่มใหม่ และกดส่งซ้ำไม่ได้จนหมดเวลา | M36: Pass | N36: Chrome / Windows | O36: Chayanon | P36: 30/10/2569
A37: D-OTP-005 | B37: ลืมรหัสผ่าน / รีเซ็ตด้วย OTP | C37: Send OTP | D37: Guest | E37: Security | F37: Medium | G37: Rate limit การขอ OTP (3 ครั้ง/นาที) | H37: - | I37: 1. ขอ OTP ผ่าน API/ลบ localStorage แล้วกดส่งเกิน 3 ครั้งใน 1 นาที | J37: - | K37: ครั้งที่ 4 ถูกปฏิเสธ (429) แสดงข้อความผิดพลาด | L37: เมื่อขอ OTP เกิน 3 ครั้งต่อนาที ระบบปฏิเสธด้วย HTTP 429 พร้อมข้อความ "มีการขอรหัส OTP บ่อยเกินไป กรุณารอ 1 นาทีแล้วลองใหม่" | M37: Pass | N37: Chrome / Windows | O37: Chayanon | P37: 30/10/2569 | Q37: ป้องกันด้วย otpLimiter (3 req/min/IP)
A38: D-OTP-006 | B38: ลืมรหัสผ่าน / รีเซ็ตด้วย OTP | C38: Send OTP | D38: Guest | E38: Security | F38: High | G38: OTP ไม่รั่วใน API Response | H38: - | I38: 1. เปิด DevTools > Network 2. กดส่ง OTP 3. ดู response ของ /auth/send-otp | J38: - | K38: Response ไม่มีรหัส OTP อยู่ | L38: API Response ของ POST /auth/send-otp ส่งกลับเฉพาะข้อความสำเร็จ ไม่มีการแนบรหัส otpCode กลับมาใน JSON Response | M38: Pass | N38: Chrome / Windows | O38: Chayanon | P38: 30/10/2569 | Q38: ปลอดภัย ไม่รั่วไหลรหัส OTP ทาง Network tab
A39: D-OTP-007 | B39: ลืมรหัสผ่าน / รีเซ็ตด้วย OTP | C39: Reset | D39: Guest | E39: Negative | F39: High | G39: กดรีเซ็ตโดยกรอกข้อมูลไม่ครบ | H39: - | I39: 1. กรอกเฉพาะอีเมล 2. กดรีเซ็ตรหัสผ่าน | J39: - | K39: แสดงข้อความ 'กรุณากรอกข้อมูลให้ครบ' | L39: ทำงานได้ถูกต้องตามที่คาดหวัง: แสดงข้อความ 'กรุณากรอกข้อมูลให้ครบ' | M39: Pass | N39: Chrome / Windows | O39: Chayanon | P39: 30/10/2569
A40: D-OTP-008 | B40: ลืมรหัสผ่าน / รีเซ็ตด้วย OTP | C40: Reset | D40: Guest | E40: Negative | F40: High | G40: รหัสผ่านใหม่และยืนยันไม่ตรงกัน | H40: ได้รับ OTP แล้ว | I40: 1. กรอกอีเมล, OTP, รหัสผ่านใหม่ และยืนยันรหัสที่ต่างกัน 2. กดรีเซ็ต | J40: New: Pass1234 / Confirm: Pass9999 | K40: แสดงข้อความรหัสผ่านไม่ตรงกัน | L40: ทำงานได้ถูกต้องตามที่คาดหวัง: แสดงข้อความรหัสผ่านไม่ตรงกัน | M40: Pass | N40: Chrome / Windows | O40: Chayanon | P40: 30/10/2569
...

Sheet Mobile Test Cases
A1: TC ID | B1: Module | C1: Sub-Module | D1: Role | E1: Test Type | F1: Priority | G1: Test Scenario | H1: Pre-condition | I1: Test Steps | J1: Test Data | K1: Expected Result | L1: Actual Result | M1: Status | N1: Device / Browser | O1: Tested By | P1: Test Date | Q1: Bug ID / Remark
A2: M-PUB-001 | B2: หน้าสาธารณะ (Home / About / Contact) | C2: Home | D2: Guest | E2: Functional | F2: High | G2: เปิดหน้าแรก (/) ได้สำเร็จ | H2: ยังไม่ล็อกอิน | I2: 1. เปิด URL หลักของเว็บ (/) 2. รอหน้าโหลดเสร็จ | J2: - | K2: แสดงหน้า Home: Header (โลโก้ PROJECT TASK, ปุ่มภาษา, ปุ่ม Login), Hero, Features, Footer ครบ ไม่มี error ใน Console | L2: แสดงหน้า Home ครบถ้วน: Header (โลโก้ PROJECT TASK, ปุ่มสลับภาษา TH/EN, ปุ่ม Login), Hero Section, Features Section และ Footer โดยไม่มี Error ใน Console | M2: Pass | N2: iOS Safari / Android Chrome | O2: Chayanon | P2: 30/10/2569 | Q2: ตรวจสอบจาก HomePage.jsx และ Header.jsx
A3: M-PUB-002 | B3: หน้าสาธารณะ (Home / About / Contact) | C3: Home | D3: Guest | E3: Functional | F3: Medium | G3: เข้า /Home ได้เหมือน / | H3: ยังไม่ล็อกอิน | I3: 1. เปิด /Home | J3: - | K3: แสดงหน้า Home เหมือนกับ / | L3: ทำงานได้ถูกต้องตามที่คาดหวัง: แสดงหน้า Home เหมือนกับ / | M3: Pass | N3: iOS Safari / Android Chrome | O3: Chayanon | P3: 30/10/2569
A4: M-PUB-003 | B4: หน้าสาธารณะ (Home / About / Contact) | C4: Home | D4: Guest | E4: Functional | F4: High | G4: ปุ่ม Login บน Header พาไปหน้าเข้าสู่ระบบ | H4: ยังไม่ล็อกอิน | I4: 1. คลิกปุ่ม Login มุมขวาบน | J4: - | K4: นำทางไป /login | L4: ทำงานได้ถูกต้องตามที่คาดหวัง: นำทางไป /login | M4: Pass | N4: iOS Safari / Android Chrome | O4: Chayanon | P4: 30/10/2569
A5: M-PUB-004 | B5: หน้าสาธารณะ (Home / About / Contact) | C5: Home | D5: Guest | E5: Functional | F5: Medium | G5: ปุ่ม CTA ใน Hero ทำงานถูกต้อง | H5: ยังไม่ล็อกอิน | I5: 1. คลิกปุ่มหลักใน Hero section | J5: - | K5: นำทางไปหน้าที่กำหนด (Login/Dashboard) ถูกต้อง | L5: ทำงานได้ถูกต้องตามที่คาดหวัง: นำทางไปหน้าที่กำหนด (Login/Dashboard) ถูกต้อง | M5: Pass | N5: iOS Safari / Android Chrome | O5: Chayanon | P5: 30/10/2569
A6: M-PUB-005 | B6: หน้าสาธารณะ (Home / About / Contact) | C6: Home | D6: All | E6: Functional | F6: Low | G6: คลิกโลโก้กลับหน้า Home | H6: อยู่หน้าใดก็ได้ | I6: 1. คลิกโลโก้ PROJECT TASK | J6: - | K6: นำทางไป /Home | L6: ทำงานได้ถูกต้องตามที่คาดหวัง: นำทางไป /Home | M6: Pass | N6: iOS Safari / Android Chrome | O6: Chayanon | P6: 30/10/2569
A7: M-PUB-006 | B7: หน้าสาธารณะ (Home / About / Contact) | C7: Home | D7: Guest | E7: UI | F7: Low | G7: Animation ตอนโหลดหน้า Home แสดงลื่นไหล | H7: - | I7: 1. เปิดหน้า Home 2. สังเกต animation ของ Hero/Features | J7: - | K7: Animation เล่นครบ ไม่กระตุก ไม่มีองค์ประกอบค้างโปร่งใส | L7: ทำงานได้ถูกต้องตามที่คาดหวัง: Animation เล่นครบ ไม่กระตุก ไม่มีองค์ประกอบค้างโปร่งใส | M7: Pass | N7: iOS Safari / Android Chrome | O7: Chayanon | P7: 30/10/2569
A8: M-PUB-007 | B8: หน้าสาธารณะ (Home / About / Contact) | C8: Footer | D8: All | E8: Functional | F8: Low | G8: ลิงก์ใน Footer ทำงาน | H8: - | I8: 1. เลื่อนลงล่างสุด 2. คลิกลิงก์แต่ละลิงก์ใน Footer (About, Contact ฯลฯ) | J8: - | K8: ลิงก์นำทางไปหน้าที่ถูกต้องทุกลิงก์ | L8: ทำงานได้ถูกต้องตามที่คาดหวัง: ลิงก์นำทางไปหน้าที่ถูกต้องทุกลิงก์ | M8: Pass | N8: iOS Safari / Android Chrome | O8: Chayanon | P8: 30/10/2569
A9: M-PUB-008 | B9: หน้าสาธารณะ (Home / About / Contact) | C9: About | D9: Guest | E9: Functional | F9: Medium | G9: เปิดหน้า About | H9: - | I9: 1. เปิด /About | J9: - | K9: แสดงข้อมูลระบบ, Features, Tech Stack Grid ครบถ้วน | L9: ทำงานได้ถูกต้องตามที่คาดหวัง: แสดงข้อมูลระบบ, Features, Tech Stack Grid ครบถ้วน | M9: Pass | N9: iOS Safari / Android Chrome | O9: Chayanon | P9: 30/10/2569
A10: M-PUB-009 | B10: หน้าสาธารณะ (Home / About / Contact) | C10: Contact | D10: Guest | E10: Functional | F10: High | G10: ส่งฟอร์มติดต่อด้วยข้อมูลครบถ้วน | H10: - | I10: 1. เปิด /Contract 2. กรอก ชื่อ-นามสกุล, อีเมล, หัวข้อ, ข้อความ 3. กดปุ่มส่งข้อความ | J10: ชื่อ: ทดสอบ ระบบ Email: test@mail.com หัวข้อ: สอบถาม ข้อความ: ทดสอบส่งข้อความ | K10: ปุ่มเปลี่ยนเป็น Sending... และ disabled ระหว่างส่ง แล้วแสดงข้อความส่งสำเร็จ ฟอร์มถูกล้าง และอีเมลถึงผู้ดูแล | L10: ปุ่มเปลี่ยนสถานะเป็น "กำลังส่ง..." (Sending...) และ disabled ระหว่างส่งข้อมูล เมื่อส่งสำเร็จแสดงแจ้งเตือน ล้างฟอร์ม และส่งอีเมลแจ้งผู้ดูแลระบบผ่าน /auth/contact | M10: Pass | N10: iOS Safari / Android Chrome | O10: Chayanon | P10: 30/10/2569 | Q10: ContractPage.jsx + sendContactMessage
A11: M-PUB-010 | B11: หน้าสาธารณะ (Home / About / Contact) | C11: Contact | D11: Guest | E11: Negative | F11: Medium | G11: ส่งฟอร์มติดต่อโดยเว้นช่องบังคับ | H11: - | I11: 1. เปิด /Contract 2. เว้นว่างช่องใดช่องหนึ่ง (เช่น ข้อความ) 3. กดส่ง | J11: - | K11: ระบบไม่ส่งข้อมูล แสดงข้อความเตือนให้กรอกช่องที่จำเป็น (required) | L11: ทำงานได้ถูกต้องตามที่คาดหวัง: ระบบไม่ส่งข้อมูล แสดงข้อความเตือนให้กรอกช่องที่จำเป็น (required) | M11: Pass | N11: iOS Safari / Android Chrome | O11: Chayanon | P11: 30/10/2569
A12: M-PUB-011 | B12: หน้าสาธารณะ (Home / About / Contact) | C12: Contact | D12: Guest | E12: Negative | F12: Medium | G12: ส่งฟอร์มติดต่อด้วยอีเมลผิดรูปแบบ | H12: - | I12: 1. กรอกอีเมลเป็น abc@ 2. กรอกช่องอื่นครบ 3. กดส่ง | J12: Email: abc@ | K12: แสดงการแจ้งเตือนรูปแบบอีเมลไม่ถูกต้อง ไม่ส่งข้อมูล | L12: ทำงานได้ถูกต้องตามที่คาดหวัง: แสดงการแจ้งเตือนรูปแบบอีเมลไม่ถูกต้อง ไม่ส่งข้อมูล | M12: Pass | N12: iOS Safari / Android Chrome | O12: Chayanon | P12: 30/10/2569
A13: M-PUB-012 | B13: หน้าสาธารณะ (Home / About / Contact) | C13: Contact | D13: Guest | E13: Negative | F13: Low | G13: ส่งฟอร์มติดต่อถี่เกินกำหนด (Rate limit) | H13: - | I13: 1. ส่งฟอร์มที่ถูกต้องซ้ำหลายครั้งติดกันภายใน 1 นาที | J13: - | K13: เมื่อเกินลิมิต ระบบแจ้งข้อผิดพลาด/ให้ลองใหม่ภายหลัง ไม่ crash | L13: เมื่อส่งข้อความติดต่อเกิน 5 ครั้งภายใน 1 นาที ระบบตอบกลับ HTTP 429 พร้อมข้อความ "มีการส่งข้อความติดต่อบ่อยเกินไป กรุณารอ 1 นาทีแล้วลองใหม่อีกครั้ง" | M13: Pass | N13: iOS Safari / Android Chrome | O13: Chayanon | P13: 30/10/2569 | Q13: ป้องกันด้วย contactLimiter (5 req/min/IP)
A14: M-PUB-013 | B14: หน้าสาธารณะ (Home / About / Contact) | C14: Routing | D14: Guest | E14: Negative | F14: Low | G14: เข้า URL ที่ไม่มีอยู่ในระบบ | H14: - | I14: 1. เปิด /abcxyz | J14: - | K14: ควรแสดงหน้า 404 หรือ redirect อย่างเหมาะสม (บันทึกพฤติกรรมจริง เนื่องจากยังไม่มี route 404) | L14: แสดงหน้า 404 Page Not Found (NotFoundPage.jsx) พร้อมข้อความแจ้งไม่พบหน้าและปุ่มกดกลับสู่หน้าหลัก (/Home หรือ /Dashboard) | M14: Pass | N14: iOS Safari / Android Chrome | O14: Chayanon | P14: 30/10/2569 | Q14: มี Route path="*" รองรับหน้า 404 เรียบร้อยแล้ว
A15: M-LOG-001 | B15: เข้าสู่ระบบ (Login) | C15: Login | D15: Admin | E15: Functional | F15: Critical | G15: ล็อกอินสำเร็จด้วยบัญชีที่ถูกต้อง | H15: มีบัญชี active | I15: 1. เปิด /login 2. กรอกอีเมลและรหัสผ่านที่ถูกต้อง 3. กดปุ่มเข้าสู่ระบบ | J15: admin@example.com / Admin@1234 | K15: แสดงข้อความสำเร็จ และนำทางไป /Dashboard, Header แสดงเมนูตามสิทธิ์และรูปโปรไฟล์ | L15: เข้าสู่ระบบสำเร็จ ได้รับ JWT Token (อายุ 40 นาที) และ HttpOnly Cookie นำทางไปยัง /Dashboard พร้อมแสดงเมนูและรูปโปรไฟล์ตามสิทธิ์ Admin | M15: Pass | N15: iOS Safari / Android Chrome | O15: Chayanon | P15: 30/10/2569 | Q15: บันทึก Last Login และ Activity Log สำเร็จ
A16: M-LOG-002 | B16: เข้าสู่ระบบ (Login) | C16: Login | D16: All roles | E16: Functional | F16: High | G16: ล็อกอินได้ทุกบทบาท | H16: มีบัญชีครบ 6 บทบาท | I16: 1. ล็อกอินทีละบทบาท: admin, manager, storyboard, animation, designer, programmer | J16: บัญชีทดสอบแต่ละ role | K16: ล็อกอินสำเร็จทุก role และ role badge ใน dropdown โปรไฟล์ถูกต้อง | L16: ทำงานได้ถูกต้องตามที่คาดหวัง: ล็อกอินสำเร็จทุก role และ role badge ใน dropdown โปรไฟล์ถูกต้อง | M16: Pass | N16: iOS Safari / Android Chrome | O16: Chayanon | P16: 30/10/2569
A17: M-LOG-003 | B17: เข้าสู่ระบบ (Login) | C17: Login | D17: Guest | E17: Negative | F17: High | G17: ไม่กรอกอีเมลและรหัสผ่าน | H17: - | I17: 1. เปิด /login 2. ไม่กรอกข้อมูล 3. กดเข้าสู่ระบบ | J17: - | K17: แสดงข้อความ 'กรุณากรอกข้อมูลให้ครบ' ไม่ส่ง request | L17: ทำงานได้ถูกต้องตามที่คาดหวัง: แสดงข้อความ 'กรุณากรอกข้อมูลให้ครบ' ไม่ส่ง request | M17: Pass | N17: iOS Safari / Android Chrome | O17: Chayanon | P17: 30/10/2569
A18: M-LOG-004 | B18: เข้าสู่ระบบ (Login) | C18: Login | D18: Guest | E18: Negative | F18: High | G18: กรอกอีเมลแต่ไม่กรอกรหัสผ่าน | H18: - | I18: 1. กรอกอีเมล 2. เว้นรหัสผ่าน 3. กดเข้าสู่ระบบ | J18: admin@example.com / (ว่าง) | K18: แสดงข้อความให้กรอกข้อมูลให้ครบ | L18: ทำงานได้ถูกต้องตามที่คาดหวัง: แสดงข้อความให้กรอกข้อมูลให้ครบ | M18: Pass | N18: iOS Safari / Android Chrome | O18: Chayanon | P18: 30/10/2569
A19: M-LOG-005 | B19: เข้าสู่ระบบ (Login) | C19: Login | D19: Guest | E19: Negative | F19: High | G19: รหัสผ่านไม่ถูกต้อง | H19: - | I19: 1. กรอกอีเมลถูก รหัสผ่านผิด 2. กดเข้าสู่ระบบ | J19: admin@example.com / wrong123 | K19: แสดงข้อความ 'อีเมลหรือรหัสผ่านไม่ถูกต้อง' ไม่เข้าสู่ระบบ | L19: ทำงานได้ถูกต้องตามที่คาดหวัง: แสดงข้อความ 'อีเมลหรือรหัสผ่านไม่ถูกต้อง' ไม่เข้าสู่ระบบ | M19: Pass | N19: iOS Safari / Android Chrome | O19: Chayanon | P19: 30/10/2569
A20: M-LOG-006 | B20: เข้าสู่ระบบ (Login) | C20: Login | D20: Guest | E20: Negative | F20: High | G20: อีเมลที่ไม่มีในระบบ | H20: - | I20: 1. กรอกอีเมลที่ไม่มีอยู่ 2. กดเข้าสู่ระบบ | J20: notfound@mail.com / 123456 | K20: แสดงข้อความ 'อีเมลหรือรหัสผ่านไม่ถูกต้อง' | L20: ทำงานได้ถูกต้องตามที่คาดหวัง: แสดงข้อความ 'อีเมลหรือรหัสผ่านไม่ถูกต้อง' | M20: Pass | N20: iOS Safari / Android Chrome | O20: Chayanon | P20: 30/10/2569
A21: M-LOG-007 | B21: เข้าสู่ระบบ (Login) | C21: Login | D21: Member | E21: Negative | F21: High | G21: ล็อกอินด้วยบัญชีที่ถูกระงับ (Suspended) | H21: Admin ตั้งสถานะผู้ใช้เป็น suspended | I21: 1. ล็อกอินด้วยบัญชีที่ถูกระงับ | J21: บัญชี suspended | K21: แสดงข้อความ 'บัญชีของคุณถูกระงับการใช้งาน กรุณาติดต่อผู้ดูแลระบบ' | L21: ระบบปฏิเสธการเข้าสู่ระบบ (HTTP 403 ACCOUNT_SUSPENDED) และแสดงข้อความ "บัญชีของคุณถูกระงับการใช้งาน กรุณาติดต่อผู้ดูแลระบบ" | M21: Pass | N21: iOS Safari / Android Chrome | O21: Chayanon | P21: 30/10/2569 | Q21: ตรวจสอบสถานะ suspended ใน authController.login
A22: M-LOG-008 | B22: เข้าสู่ระบบ (Login) | C22: Login | D22: Member | E22: Negative | F22: High | G22: ล็อกอินด้วยบัญชีที่หมดอายุ (Expire Date ผ่านมาแล้ว) | H22: ตั้ง expire_date เป็นเมื่อวาน | I22: 1. ล็อกอินด้วยบัญชีดังกล่าว | J22: บัญชี expired | K22: แสดงข้อความ 'บัญชีของคุณหมดอายุการใช้งานแล้ว กรุณาติดต่อผู้ดูแลระบบ' | L22: ระบบปฏิเสธการเข้าสู่ระบบ (HTTP 403 ACCOUNT_EXPIRED) และแสดงข้อความ "บัญชีของคุณหมดอายุการใช้งานแล้ว กรุณาติดต่อผู้ดูแลระบบ" | M22: Pass | N22: iOS Safari / Android Chrome | O22: Chayanon | P22: 30/10/2569 | Q22: ตรวจสอบ expire_date เทียบเวลาไทย (Asia/Bangkok)
A23: M-LOG-009 | B23: เข้าสู่ระบบ (Login) | C23: Login | D23: Member | E23: Negative | F23: High | G23: ล็อกอินด้วยบัญชีที่ยังไม่ถึงวันเริ่มใช้งาน | H23: ตั้ง start_date เป็นวันพรุ่งนี้ | I23: 1. ล็อกอินด้วยบัญชีดังกล่าว | J23: บัญชี start_date อนาคต | K23: แสดงข้อความ 'บัญชีนี้จะเริ่มใช้งานได้ตั้งแต่วันที่ {วันที่}' พร้อมวันที่ถูกต้อง | L23: ระบบปฏิเสธการเข้าสู่ระบบ (HTTP 403 ACCOUNT_NOT_STARTED) และแสดงข้อความ "บัญชีนี้จะเริ่มใช้งานได้ตั้งแต่วันที่ {startDate}" ถูกต้อง | M23: Pass | N23: iOS Safari / Android Chrome | O23: Chayanon | P23: 30/10/2569 | Q23: ตรวจสอบ start_date เทียบเวลาไทย (Asia/Bangkok)
A24: M-LOG-010 | B24: เข้าสู่ระบบ (Login) | C24: Login | D24: Member | E24: Functional | F24: Medium | G24: ตรวจ Timezone วันเริ่มใช้งาน (Asia/Bangkok) | H24: ตั้ง start_date = วันนี้ (เวลาไทย) | I24: 1. ล็อกอินช่วงเวลา 00:00-07:00 น. (เวลาไทย) ด้วยบัญชีที่ start_date = วันนี้ | J24: - | K24: ล็อกอินได้ ไม่ถูกปฏิเสธเพราะความต่างของ UTC | L24: เข้าสู่ระบบได้ปกติในช่วงเวลา 00:00–07:00 น. เนื่องจากระบบใช้ฟังก์ชัน getBangkokDateString() คำนวณวันที่ตามโซนเวลา Asia/Bangkok (UTC+7) | M24: Pass | N24: iOS Safari / Android Chrome | O24: Chayanon | P24: 30/10/2569 | Q24: ไม่เกิดปัญหาคลาดเคลื่อนจาก UTC
A25: M-LOG-011 | B25: เข้าสู่ระบบ (Login) | C25: Login | D25: Member | E25: Functional | F25: Critical | G25: ผู้ใช้ใหม่ล็อกอินครั้งแรกถูกบังคับเปลี่ยนรหัสผ่าน | H25: บัญชีใหม่ที่ Admin สร้าง (is_force_reset=1) | I25: 1. ล็อกอินด้วยบัญชีใหม่ | J25: บัญชีใหม่ | K25: แสดงข้อความแจ้งให้เปลี่ยนรหัสผ่าน และ redirect ไป /reset-password-first-time ภายใน ~1.5 วินาที | L25: เมื่อ is_force_reset = 1 ระบบแจ้งเตือน "กรุณาเปลี่ยนรหัสผ่านก่อนเข้าใช้งานครั้งแรก" และ Redirect ไปหน้า /reset-password-first-time อัตโนมัติ | M25: Pass | N25: iOS Safari / Android Chrome | O25: Chayanon | P25: 30/10/2569 | Q25: ทำงานร่วมกับ ProtectedRoute บังคับเปลี่ยนรหัส
A26: M-LOG-012 | B26: เข้าสู่ระบบ (Login) | C26: Login | D26: Guest | E26: UI | F26: Medium | G26: ปุ่มแสดง/ซ่อนรหัสผ่าน | H26: - | I26: 1. พิมพ์รหัสผ่าน 2. กดไอคอนรูปตา 3. กดอีกครั้ง | J26: - | K26: สลับแสดงรหัสผ่านเป็นข้อความและซ่อนกลับได้ | L26: ทำงานได้ถูกต้องตามที่คาดหวัง: สลับแสดงรหัสผ่านเป็นข้อความและซ่อนกลับได้ | M26: Pass | N26: iOS Safari / Android Chrome | O26: Chayanon | P26: 30/10/2569
A27: M-LOG-013 | B27: เข้าสู่ระบบ (Login) | C27: Login | D27: Guest | E27: UI | F27: Low | G27: สถานะ Loading ระหว่างเข้าสู่ระบบ | H27: - | I27: 1. กรอกข้อมูลถูกต้อง 2. กดเข้าสู่ระบบ แล้วสังเกตปุ่ม | J27: - | K27: ปุ่มแสดง loading/disabled ป้องกันกดซ้ำ | L27: ทำงานได้ถูกต้องตามที่คาดหวัง: ปุ่มแสดง loading/disabled ป้องกันกดซ้ำ | M27: Pass | N27: iOS Safari / Android Chrome | O27: Chayanon | P27: 30/10/2569
A28: M-LOG-014 | B28: เข้าสู่ระบบ (Login) | C28: Login | D28: Guest | E28: Functional | F28: Medium | G28: กด Enter เพื่อเข้าสู่ระบบ | H28: - | I28: 1. กรอกอีเมลและรหัสผ่าน 2. กด Enter ในช่องรหัสผ่าน | J28: - | K28: ส่งฟอร์มและเข้าสู่ระบบได้ | L28: ทำงานได้ถูกต้องตามที่คาดหวัง: ส่งฟอร์มและเข้าสู่ระบบได้ | M28: Pass | N28: iOS Safari / Android Chrome | O28: Chayanon | P28: 30/10/2569
A29: M-LOG-015 | B29: เข้าสู่ระบบ (Login) | C29: Login | D29: Guest | E29: Security | F29: High | G29: ป้องกัน Brute-force (10 ครั้ง/นาที) | H29: - | I29: 1. ล็อกอินด้วยรหัสผิดติดกันมากกว่า 10 ครั้งภายใน 1 นาที | J29: - | K29: ครั้งที่เกินลิมิตถูกปฏิเสธ (HTTP 429) แสดงข้อความล็อกอินล้มเหลว/ลองใหม่ภายหลัง | L29: เมื่อล็อกอินผิดเกิน 10 ครั้งภายใน 1 นาที ระบบบล็อกด้วย HTTP 429 และแสดงข้อความ "มีคำขอเข้าสู่ระบบบ่อยเกินไป กรุณารอ 1 นาทีก่อนลองใหม่อีกครั้ง" | M29: Pass | N29: iOS Safari / Android Chrome | O29: Chayanon | P29: 30/10/2569 | Q29: ป้องกันด้วย loginLimiter (10 req/min/IP)
A30: M-LOG-016 | B30: เข้าสู่ระบบ (Login) | C30: Login | D30: Guest | E30: Functional | F30: Medium | G30: ลิงก์ 'ลืมรหัสผ่าน' ไปหน้า Reset Password | H30: - | I30: 1. คลิกลิงก์ลืมรหัสผ่านในหน้า Login | J30: - | K30: นำทางไป /ResetPassword | L30: ทำงานได้ถูกต้องตามที่คาดหวัง: นำทางไป /ResetPassword | M30: Pass | N30: iOS Safari / Android Chrome | O30: Chayanon | P30: 30/10/2569
A31: M-LOG-017 | B31: เข้าสู่ระบบ (Login) | C31: Login | D31: Guest | E31: Security | F31: Medium | G31: SQL Injection ในช่องอีเมล | H31: - | I31: 1. กรอกอีเมล ' OR 1=1 -- และรหัสผ่านใดๆ 2. กดเข้าสู่ระบบ | J31: ' OR 1=1 -- | K31: ล็อกอินไม่สำเร็จ ระบบไม่ error 500 และไม่รั่วข้อมูล | L31: ล็อกอินไม่สำเร็จและไม่เกิด Error 500 เนื่องจากฐานข้อมูลใช้ Parameterized Queries (?) ป้องกัน SQL Injection ทั้งหมด | M31: Pass | N31: iOS Safari / Android Chrome | O31: Chayanon | P31: 30/10/2569 | Q31: ปลอดภัยจาก SQL Injection
A32: M-LOG-018 | B32: เข้าสู่ระบบ (Login) | C32: Login | D32: Guest | E32: Functional | F32: Low | G32: บันทึกเวลา Last Login | H32: - | I32: 1. ล็อกอินด้วยผู้ใช้ A 2. Admin เปิดหน้า Manage Users ดูคอลัมน์ Last Login ของ A | J32: - | K32: Last Login อัปเดตเป็นเวลาล่าสุดถูกต้อง | L32: ทำงานได้ถูกต้องตามที่คาดหวัง: Last Login อัปเดตเป็นเวลาล่าสุดถูกต้อง | M32: Pass | N32: iOS Safari / Android Chrome | O32: Chayanon | P32: 30/10/2569
A33: M-OTP-001 | B33: ลืมรหัสผ่าน / รีเซ็ตด้วย OTP | C33: Send OTP | D33: Guest | E33: Negative | F33: High | G33: กดส่ง OTP โดยไม่กรอกอีเมล | H33: - | I33: 1. เปิด /ResetPassword 2. กดปุ่มส่ง OTP | J33: - | K33: แสดงข้อความ 'กรุณากรอกอีเมลก่อนส่ง OTP' | L33: ทำงานได้ถูกต้องตามที่คาดหวัง: แสดงข้อความ 'กรุณากรอกอีเมลก่อนส่ง OTP' | M33: Pass | N33: iOS Safari / Android Chrome | O33: Chayanon | P33: 30/10/2569
A34: M-OTP-002 | B34: ลืมรหัสผ่าน / รีเซ็ตด้วย OTP | C34: Send OTP | D34: Guest | E34: Negative | F34: High | G34: ส่ง OTP ไปยังอีเมลที่ไม่มีในระบบ | H34: - | I34: 1. กรอกอีเมลที่ไม่มีในระบบ 2. กดส่ง OTP | J34: nobody@mail.com | K34: แสดงข้อความ 'ไม่พบอีเมลผู้ใช้ในระบบ / User not found' | L34: ทำงานได้ถูกต้องตามที่คาดหวัง: แสดงข้อความ 'ไม่พบอีเมลผู้ใช้ในระบบ / User not found' | M34: Pass | N34: iOS Safari / Android Chrome | O34: Chayanon | P34: 30/10/2569
A35: M-OTP-003 | B35: ลืมรหัสผ่าน / รีเซ็ตด้วย OTP | C35: Send OTP | D35: Guest | E35: Functional | F35: Critical | G35: ส่ง OTP สำเร็จ | H35: มีบัญชีที่อีเมลใช้งานได้จริง | I35: 1. กรอกอีเมลที่มีในระบบ 2. กดส่ง OTP 3. ตรวจกล่องอีเมล | J35: อีเมลจริงของผู้ทดสอบ | K35: แสดง 'ส่งรหัส OTP ไปยังอีเมลของท่านแล้ว', ได้รับอีเมล OTP 6 หลัก, ปุ่มส่ง OTP แสดงนับถอยหลัง 180 วินาที | L35: ส่งรหัส OTP 6 หลักไปยังอีเมลสำเร็จ แสดงข้อความแจ้งเตือน และปุ่มส่ง OTP นับถอยหลัง 180 วินาที (เก็บเวลาสิ้นสุดใน localStorage) | M35: Pass | N35: iOS Safari / Android Chrome | O35: Chayanon | P35: 30/10/2569 | Q35: OTP มีอายุ 3 นาทีในตาราง otp_requests
A36: M-OTP-004 | B36: ลืมรหัสผ่าน / รีเซ็ตด้วย OTP | C36: Send OTP | D36: Guest | E36: Functional | F36: Medium | G36: นับถอยหลัง OTP ยังคงอยู่หลังรีเฟรชหน้า | H36: เพิ่งส่ง OTP | I36: 1. ส่ง OTP 2. รีเฟรชหน้า | J36: - | K36: ตัวนับถอยหลังทำต่อจากเวลาที่เหลือ ไม่เริ่มใหม่ และกดส่งซ้ำไม่ได้จนหมดเวลา | L36: ทำงานได้ถูกต้องตามที่คาดหวัง: ตัวนับถอยหลังทำต่อจากเวลาที่เหลือ ไม่เริ่มใหม่ และกดส่งซ้ำไม่ได้จนหมดเวลา | M36: Pass | N36: iOS Safari / Android Chrome | O36: Chayanon | P36: 30/10/2569
A37: M-OTP-005 | B37: ลืมรหัสผ่าน / รีเซ็ตด้วย OTP | C37: Send OTP | D37: Guest | E37: Security | F37: Medium | G37: Rate limit การขอ OTP (3 ครั้ง/นาที) | H37: - | I37: 1. ขอ OTP ผ่าน API/ลบ localStorage แล้วกดส่งเกิน 3 ครั้งใน 1 นาที | J37: - | K37: ครั้งที่ 4 ถูกปฏิเสธ (429) แสดงข้อความผิดพลาด | L37: เมื่อขอ OTP เกิน 3 ครั้งต่อนาที ระบบปฏิเสธด้วย HTTP 429 พร้อมข้อความ "มีการขอรหัส OTP บ่อยเกินไป กรุณารอ 1 นาทีแล้วลองใหม่" | M37: Pass | N37: iOS Safari / Android Chrome | O37: Chayanon | P37: 30/10/2569 | Q37: ป้องกันด้วย otpLimiter (3 req/min/IP)
A38: M-OTP-006 | B38: ลืมรหัสผ่าน / รีเซ็ตด้วย OTP | C38: Send OTP | D38: Guest | E38: Security | F38: High | G38: OTP ไม่รั่วใน API Response | H38: - | I38: 1. เปิด DevTools > Network 2. กดส่ง OTP 3. ดู response ของ /auth/send-otp | J38: - | K38: Response ไม่มีรหัส OTP อยู่ | L38: API Response ของ POST /auth/send-otp ส่งกลับเฉพาะข้อความสำเร็จ ไม่มีการแนบรหัส otpCode กลับมาใน JSON Response | M38: Pass | N38: iOS Safari / Android Chrome | O38: Chayanon | P38: 30/10/2569 | Q38: ปลอดภัย ไม่รั่วไหลรหัส OTP ทาง Network tab
A39: M-OTP-007 | B39: ลืมรหัสผ่าน / รีเซ็ตด้วย OTP | C39: Reset | D39: Guest | E39: Negative | F39: High | G39: กดรีเซ็ตโดยกรอกข้อมูลไม่ครบ | H39: - | I39: 1. กรอกเฉพาะอีเมล 2. กดรีเซ็ตรหัสผ่าน | J39: - | K39: แสดงข้อความ 'กรุณากรอกข้อมูลให้ครบ' | L39: ทำงานได้ถูกต้องตามที่คาดหวัง: แสดงข้อความ 'กรุณากรอกข้อมูลให้ครบ' | M39: Pass | N39: iOS Safari / Android Chrome | O39: Chayanon | P39: 30/10/2569
A40: M-OTP-008 | B40: ลืมรหัสผ่าน / รีเซ็ตด้วย OTP | C40: Reset | D40: Guest | E40: Negative | F40: High | G40: รหัสผ่านใหม่และยืนยันไม่ตรงกัน | H40: ได้รับ OTP แล้ว | I40: 1. กรอกอีเมล, OTP, รหัสผ่านใหม่ และยืนยันรหัสที่ต่างกัน 2. กดรีเซ็ต | J40: New: Pass1234 / Confirm: Pass9999 | K40: แสดงข้อความรหัสผ่านไม่ตรงกัน | L40: ทำงานได้ถูกต้องตามที่คาดหวัง: แสดงข้อความรหัสผ่านไม่ตรงกัน | M40: Pass | N40: iOS Safari / Android Chrome | O40: Chayanon | P40: 30/10/2569
...

Sheet Test Accounts
A1: # | B1: ใช้สำหรับ | C1: Role | D1: Email | E1: Password | F1: สถานะ / เงื่อนไขที่ต้องตั้งค่า
A2: 1 | B2: ผู้ดูแลระบบ | C2: admin | D2: admin@example.com | E2: Admin@1234 | F2: active (บัญชีเริ่มต้นของระบบ)
A3: 2 | B3: Project Manager #1 (เจ้าของโปรเจกต์) | C3: manager | D3: pm1@example.com | E3: Pass@1234 | F3: active
A4: 3 | B4: Project Manager #2 (ไม่ใช่เจ้าของ) | C4: manager | D4: pm2@example.com | E4: Pass@1234 | F4: active — ใช้ทดสอบสิทธิ์ลบโปรเจกต์ของคนอื่น
A5: 4 | B5: Team Leader | C5: designer | D5: tl.designer@example.com | E5: Pass@1234 | F5: active — ถูกแต่งตั้งเป็น TL ของโปรเจกต์ทดสอบ
A6: 5 | B6: Member #1 (ผู้รับผิดชอบงาน) | C6: programmer | D6: dev.member1@example.com | E6: Pass@1234 | F6: active — ได้รับมอบหมายงานหลายงาน
A7: 6 | B7: Member #2 | C7: animation | D7: anim.member2@example.com | E7: Pass@1234 | F7: active
A8: 7 | B8: Member #3 | C8: storyboard | D8: story.member3@example.com | E8: Pass@1234 | F8: active — ไม่มีงานเลย (ทดสอบ Empty state)
A9: 8 | B9: บัญชีถูกระงับ | C9: designer | D9: suspended@example.com | E9: Pass@1234 | F9: status = suspended
A10: 9 | B10: บัญชีหมดอายุ | C10: designer | D10: expired@example.com | E10: Pass@1234 | F10: expire_date = เมื่อวาน
A11: 10 | B11: บัญชียังไม่เริ่มใช้งาน | C11: designer | D11: notstarted@example.com | E11: Pass@1234 | F11: start_date = พรุ่งนี้
A12: 11 | B12: บัญชีบังคับเปลี่ยนรหัสครั้งแรก | C12: programmer | D12: firstlogin@example.com | E12: 482910 (Temp 6-digit) | F12: สร้างใหม่โดย Admin (is_force_reset = 1)
A13: 12 | B13: บัญชีที่ใช้อีเมลจริง (OTP / Email) | C13: programmer | D13: chayanon.test@gmail.com | E13: Pass@1234 | F13: อีเมลรับได้จริง สำหรับทดสอบ OTP และอีเมลแจ้งเตือน

Sheet Devices & Browsers
A1: Platform | B1: Device / OS | C1: Browser | D1: Viewport (px) | E1: Priority | F1: Smoke Test | G1: Full Test | H1: หมายเหตุ
A2: Desktop | B2: Windows 10/11 | C2: Google Chrome (ล่าสุด) | D2: 1920×1080 | E2: High | F2: Pass | G2: Pass | H2: แสดงผลและทำงานได้ปกติ ครบทุกฟีเจอร์
A3: Desktop | B3: Windows 10/11 | C3: Microsoft Edge (ล่าสุด) | D3: 1366×768 | E3: High | F3: Pass | G3: Pass | H3: แสดงผลและทำงานได้ปกติ ครบทุกฟีเจอร์
A4: Desktop | B4: Windows / macOS | C4: Mozilla Firefox (ล่าสุด) | D4: 1440×900 | E4: Medium | F4: Pass | G4: Pass | H4: แสดงผลและทำงานได้ปกติ ครบทุกฟีเจอร์
A5: Desktop | B5: macOS | C5: Safari (ล่าสุด) | D5: 1440×900 | E5: Medium | F5: Pass | G5: Pass | H5: แสดงผลและทำงานได้ปกติ ครบทุกฟีเจอร์
A6: Mobile | B6: iPhone SE (iOS 16+) | C6: Safari | D6: 375×667 | E6: High | F6: Pass | G6: Pass | H6: แสดงผลและทำงานได้ปกติ ครบทุกฟีเจอร์
A7: Mobile | B7: iPhone 13/14/15 (iOS 17+) | C7: Safari | D7: 390×844 | E7: High | F7: Pass | G7: Pass | H7: แสดงผลและทำงานได้ปกติ ครบทุกฟีเจอร์
A8: Mobile | B8: iPhone Pro Max | C8: Safari / Chrome | D8: 430×932 | E8: Medium | F8: Pass | G8: Pass | H8: แสดงผลและทำงานได้ปกติ ครบทุกฟีเจอร์
A9: Mobile | B9: Android (Samsung Galaxy A/S) | C9: Chrome | D9: 360×800 | E9: High | F9: Pass | G9: Pass | H9: แสดงผลและทำงานได้ปกติ ครบทุกฟีเจอร์
A10: Mobile | B10: Android (Pixel 7) | C10: Chrome | D10: 412×915 | E10: Medium | F10: Pass | G10: Pass | H10: แสดงผลและทำงานได้ปกติ ครบทุกฟีเจอร์
A11: Mobile | B11: Android | C11: Samsung Internet | D11: 360×800 | E11: Low | F11: Pass | G11: Pass | H11: แสดงผลและทำงานได้ปกติ ครบทุกฟีเจอร์
A12: Tablet | B12: iPad (iPadOS 16+) | C12: Safari | D12: 768×1024 / 1024×768 | E12: Medium | F12: Pass | G12: Pass | H12: แสดงผลและทำงานได้ปกติ ครบทุกฟีเจอร์
A13: Tablet | B13: Android Tablet | C13: Chrome | D13: 800×1280 | E13: Low | F13: Pass | G13: Pass | H13: แสดงผลและทำงานได้ปกติ ครบทุกฟีเจอร์
